Workbook

Sheet Validation Sample
A1: VALIDATION SAMPLE: 20 Occupations — Full Task Decomposition
A2: For each occupation: review Claude's % allocation, enter your estimate in the green column, mark Agree? (Y/N), add notes. Totals must sum to 100%.
A4: SOC 1111: Chief executives and senior officials | E4: Emp: 167,737 | F4: Raw: 48.5% | G4: PI: 29.1% | H4: Hrs/wk: 10.8
A5: Reasoning: Senior leadership. Expect heavy Strategic Judgement (25-30%), Negotiation (10-15%), Supervision (15-20%). Minimal manual/physical.
A6: Task | B6: AI Score | C6: Claude % | D6: Contribution | E6: Your % | F6: Your Contrib | G6: Agree? | H6: Notes
A7: T01 Structured Data Entry & Proc | B7: 0.92 | C7: 1 | D7: 0.009 | F7: =IF(E7="","",(E7*B7/100))
A8: T02 Routine Text Generation | B8: 0.88 | C8: 3 | D8: 0.026 | F8: =IF(E8="","",(E8*B8/100))
A9: T03 Information Retrieval & Synt | B9: 0.85 | C9: 8 | D9: 0.068 | F9: =IF(E9="","",(E9*B9/100))
A10: T04 Scheduling & Coordination | B10: 0.82 | C10: 5 | D10: 0.041 | F10: =IF(E10="","",(E10*B10/100))
A11: T05 Routine Numerical Analysis | B11: 0.8 | C11: 5 | D11: 0.04 | F11: =IF(E11="","",(E11*B11/100))
A12: T06 Classification & Sorting | B12: 0.78 | C12: 1 | D12: 0.008 | F12: =IF(E12="","",(E12*B12/100))
A13: T07 Complex Document Drafting | B13: 0.7 | C13: 12 | D13: 0.084 | F13: =IF(E13="","",(E13*B13/100))
A14: T08 Customer/Client Communicatio | B14: 0.65 | C14: 5 | D14: 0.033 | F14: =IF(E14="","",(E14*B14/100))
A15: T09 Translation & Language Servi | B15: 0.75 | C15: 0 | D15: 0 | F15: =IF(E15="","",(E15*B15/100))
A16: T10 Technical Analysis & Problem | B16: 0.55 | C16: 2 | D16: 0.011 | F16: =IF(E16="","",(E16*B16/100))
A17: T11 Creative Design & Content | B17: 0.5 | C17: 0 | D17: 0 | F17: =IF(E17="","",(E17*B17/100))
A18: T12 Strategic Judgement & Decisi | B18: 0.35 | C18: 28 | D18: 0.098 | F18: =IF(E18="","",(E18*B18/100))
... A24: T18 Outdoor/Physical Labour | B24: 0.05 | C24: 0 | D24: 0 | F24: =IF(E24="","",(E24*B24/100))
A25: TOTAL | C25: 100 | D25: 0.485 | E25: =SUM(E7:E24) -> 0 | F25: =SUM(F7:F24) -> 0
A27: SOC 2112: Biological scientists | E27: Emp: 75,214 | F27: Raw: 64.3% | G27: PI: 38.6% | H27: Hrs/wk: 14.3
A28: Reasoning: Lab scientists. Expect heavy Research/Info Retrieval (15-20%) and Technical Analysis (20-25%). Some manual lab work (5-10%).
A29: Task | B29: AI Score | C29: Claude % | D29: Contribution | E29: Your % | F29: Your Contrib | G29: Agree? | H29: Notes
A30: T01 Structured Data Entry & Proc | B30: 0.92 | C30: 5 | D30: 0.046 | F30: =IF(E30="","",(E30*B30/100))
A31: T02 Routine Text Generation | B31: 0.88 | C31: 3 | D31: 0.026 | F31: =IF(E31="","",(E31*B31/100))
A32: T03 Information Retrieval & Synt | B32: 0.85 | C32: 18 | D32: 0.153 | F32: =IF(E32="","",(E32*B32/100))
A33: T04 Scheduling & Coordination | B33: 0.82 | C33: 2 | D33: 0.016 | F33: =IF(E33="","",(E33*B33/100))
A34: T05 Routine Numerical Analysis | B34: 0.8 | C34: 8 | D34: 0.064 | F34: =IF(E34="","",(E34*B34/100))
A35: T06 Classification & Sorting | B35: 0.78 | C35: 5 | D35: 0.039 | F35: =IF(E35="","",(E35*B35/100))
A36: T07 Complex Document Drafting | B36: 0.7 | C36: 12 | D36: 0.084 | F36: =IF(E36="","",(E36*B36/100))
A37: T08 Customer/Client Communicatio | B37: 0.65 | C37: 2 | D37: 0.013 | F37: =IF(E37="","",(E37*B37/100))
A38: T09 Translation & Language Servi | B38: 0.75 | C38: 1 | D38: 0.007 | F38: =IF(E38="","",(E38*B38/100))
A39: T10 Technical Analysis & Problem | B39: 0.55 | C39: 25 | D39: 0.138 | F39: =IF(E39="","",(E39*B39/100))
A40: T11 Creative Design & Content | B40: 0.5 | C40: 0 | D40: 0 | F40: =IF(E40="","",(E40*B40/100))
A41: T12 Strategic Judgement & Decisi | B41: 0.35 | C41: 8 | D41: 0.028 | F41: =IF(E41="","",(E41*B41/100))
... A47: T18 Outdoor/Physical Labour | B47: 0.05 | C47: 0 | D47: 0 | F47: =IF(E47="","",(E47*B47/100))
A48: TOTAL | C48: 100 | D48: 0.643 | E48: =SUM(E30:E47) -> 0 | F48: =SUM(F30:F47) -> 0
A50: SOC 2411: Barristers and judges | E50: Emp: 77,065 | F50: Raw: 60.0% | G50: PI: 36.0% | H50: Hrs/wk: 13.3
A51: Reasoning: Solicitors. Expect heavy Complex Document Drafting (20-25%), Research (15-20%), Strategic Judgement (10-15%). Zero physical.
A52: Task | B52: AI Score | C52: Claude % | D52: Contribution | E52: Your % | F52: Your Contrib | G52: Agree? | H52: Notes
A53: T01 Structured Data Entry & Proc | B53: 0.92 | C53: 2 | D53: 0.018 | F53: =IF(E53="","",(E53*B53/100))
...

Sheet Methodology
B1: AWA AI IMPACT ASSESSMENT: UK OCCUPATIONS (SOC 2020)
B2: Full 412 Unit Group Task Decomposition Model — May 2026 Frontier Calibration
B4: METHODOLOGY
B5: This model estimates the practical impact of current AI capabilities on UK occupations using a task decomposition approach.
B6: It measures two distinct effects: task substitution (time saved on existing work) and capability amplification (new productive output AI enables).
B8: APPROACH
B9: 1. Define 18 standardised task categories covering all work activities, each scored for AI susceptibility (0–1)
B10: 2. Scores calibrated to May 2026 frontier capability (agentic AI, production video gen, enterprise Copilot)
B11: 3. Estimate time allocation (%) across 18 tasks for each of 412 SOC 2020 unit groups
B12: 4. Calculate AI exposure as weighted sum: SUMPRODUCT(task_time% × task_susceptibility)
B13: 5. Apply sector-specific adoption discount (0.48–0.60) reflecting differential deployment rates
B14: 6. Apply capability amplification multiplier (1.0×–2.5×) by occupational family
... B38: 1.0–1.1× — Trades, operatives, elementary (minimal amplification)

Sheet Task Categories
A1: Task ID | B1: Task Category | C1: AI Susceptibility (May 2026) | D1: Exposure Band | E1: Research Anchor / Citation
A2: T01 | B2: Structured Data Entry & Processing | C2: 0.96 | D2: HIGH | E2: Eloundou E1 direct; ILO 0.85-0.95 | F2: 0.92
A3: T02 | B3: Routine Text Generation | C3: 0.94 | D3: HIGH | E3: Eloundou E1; ILO 0.80+ | F3: 0.88
A4: T03 | B4: Information Retrieval & Synthesis | C4: 0.93 | D4: HIGH | E4: Eloundou E1-E2; Felten high LM | F4: 0.85
A5: T04 | B5: Scheduling & Coordination | C5: 0.9 | D5: HIGH | E5: ILO Gmyrek 0.70-0.85 | F5: 0.82
A6: T05 | B6: Routine Numerical Analysis | C6: 0.88 | D6: HIGH | E6: Eloundou E1-E2; OECD high | F6: 0.8
A7: T06 | B7: Classification & Sorting | C7: 0.88 | D7: HIGH | E7: ILO Gmyrek 0.70-0.85 | F7: 0.78
A8: T07 | B8: Complex Document Drafting | C8: 0.85 | D8: MODERATE-HIGH | E8: Eloundou E2; ILO 0.55-0.75 | F8: 0.7
A9: T08 | B9: Customer/Client Communication | C9: 0.82 | D9: MODERATE-HIGH | E9: ILO Gmyrek 0.50-0.75 | F9: 0.65
A10: T09 | B10: Translation & Language Services | C10: 0.82 | D10: HIGH | E10: Eloundou E1; Felten highest LM | F10: 0.75
A11: T10 | B11: Technical Analysis & Problem-Solving | C11: 0.78 | D11: MODERATE-HIGH | E11: Eloundou E2; OECD moderate | F11: 0.55
A12: T11 | B12: Creative Design & Content | C12: 0.8 | D12: MODERATE-HIGH | E12: Felten moderate-high; Eloundou E1-E2 | F12: 0.5
A13: T12 | B13: Strategic Judgement & Decision-Making | C13: 0.58 | D13: MODERATE | E13: Eloundou E0-E1; OECD low high-stakes | F13: 0.35
... A19: T18 | B19: Outdoor/Physical Labour | C19: 0.07 | D19: LOW | E19: All studies 0.02-0.08 | F19: 0.05
A21: ADOPTION DISCOUNT FACTOR | C21: 0.6
A22: Standard Weekly Hours | C22: 37
A24: Scores (horizontal for SUMPRODUCT) | B24: =C2 -> 0.96 | C24: =C3 -> 0.94 | D24: =C4 -> 0.93 | E24: =C5 -> 0.9 | F24: =C6 -> 0.88 | G24: =C7 -> 0.88 | H24: =C8 -> 0.85 | I24: =C9 -> 0.82 | J24: =C10 -> 0.82 | K24: =C11 -> 0.78 | L24: =C12 -> 0.8 | M24: =C13 -> 0.58 | N24: =C14 -> 0.45 | O24: =C15 -> 0.6 | P24: =C16 -> 0.35 | Q24: =C17 -> 0.2 | R24: =C18 -> 0.13 | S24: =C19 -> 0.07

Sheet Role Profiles
A1: SOC Code | B1: Occupation Title | C1: Sub-Major Group | D1: T01 Structured Data Entry & Processing | E1: T02 Routine Text Generation | F1: T03 Information Retrieval & Synthesis | G1: T04 Scheduling & Coordination | H1: T05 Routine Numerical Analysis | I1: T06 Classification & Sorting | J1: T07 Complex Document Drafting | K1: T08 Customer/Client Communication | L1: T09 Translation & Language Services | M1: T10 Technical Analysis & Problem-Solving | N1: T11 Creative Design & Content | O1: T12 Strategic Judgement & Decision-Making | P1: T13 Negotiation & Persuasion | Q1: T14 Teaching, Training & Mentoring | R1: T15 Supervision & People Management | S1: T16 Physical Care & Personal Service | T1: T17 Skilled Manual & Technical Operations | U1: T18 Outdoor/Physical Labour | V1: CHECK (=100)
A2: 1111 | B2: Chief executives and senior officials | C2: Corporate Managers & Directors | D2: 1 | E2: 3 | F2: 8 | G2: 5 | H2: 5 | I2: 1 | J2: 12 | K2: 5 | L2: 0 | M2: 2 | N2: 0 | O2: 28 | P2: 12 | Q2: 2 | R2: 14 | S2: 0 | T2: 2 | U2: 0 | V2: =SUM(D2:U2) -> 100
A3: 1112 | B3: Elected officers and representatives | C3: Corporate Managers & Directors | D3: 1 | E3: 3 | F3: 8 | G3: 5 | H3: 2 | I3: 1 | J3: 15 | K3: 10 | L3: 0 | M3: 1 | N3: 0 | O3: 20 | P3: 15 | Q3: 5 | R3: 10 | S3: 0 | T3: 2 | U3: 2 | V3: =SUM(D3:U3) -> 100
A4: 1113 | B4: Senior police officers | C4: Corporate Managers & Directors | D4: 2 | E4: 3 | F4: 5 | G4: 5 | H4: 3 | I4: 3 | J4: 10 | K4: 5 | L4: 0 | M4: 3 | N4: 0 | O4: 20 | P4: 8 | Q4: 5 | R4: 15 | S4: 0 | T4: 8 | U4: 5 | V4: =SUM(D4:U4) -> 100
A5: 1114 | B5: Officers in armed forces | C5: Corporate Managers & Directors | D5: 2 | E5: 3 | F5: 5 | G5: 8 | H5: 3 | I5: 2 | J5: 8 | K5: 5 | L5: 0 | M5: 5 | N5: 0 | O5: 18 | P5: 5 | Q5: 8 | R5: 15 | S5: 0 | T5: 8 | U5: 5 | V5: =SUM(D5:U5) -> 100
A6: 1115 | B6: Senior officers in fire, ambulance, prison and related services | C6: Corporate Managers & Directors | D6: 2 | E6: 3 | F6: 5 | G6: 5 | H6: 3 | I6: 3 | J6: 10 | K6: 5 | L6: 0 | M6: 3 | N6: 0 | O6: 20 | P6: 5 | Q6: 5 | R6: 15 | S6: 0 | T6: 8 | U6: 8 | V6: =SUM(D6:U6) -> 100
A7: 1131 | B7: Financial managers and directors | C7: Corporate Managers & Directors | D7: 3 | E7: 3 | F7: 5 | G7: 5 | H7: 15 | I7: 3 | J7: 10 | K7: 5 | L7: 0 | M7: 5 | N7: 0 | O7: 18 | P7: 8 | Q7: 2 | R7: 12 | S7: 0 | T7: 3 | U7: 3 | V7: =SUM(D7:U7) -> 100
A8: 1132 | B8: Marketing, sales and advertising directors | C8: Corporate Managers & Directors | D8: 2 | E8: 5 | F8: 8 | G8: 5 | H8: 5 | I8: 2 | J8: 12 | K8: 8 | L8: 1 | M8: 2 | N8: 5 | O8: 15 | P8: 15 | Q8: 3 | R8: 10 | S8: 0 | T8: 2 | U8: 0 | V8: =SUM(D8:U8) -> 100
A9: 1133 | B9: Purchasing managers and directors | C9: Corporate Managers & Directors | D9: 3 | E9: 3 | F9: 5 | G9: 5 | H9: 10 | I9: 5 | J9: 5 | K9: 8 | L9: 0 | M9: 5 | N9: 0 | O9: 15 | P9: 15 | Q9: 2 | R9: 12 | S9: 0 | T9: 5 | U9: 2 | V9: =SUM(D9:U9) -> 100
A10: 1134 | B10: Human resource managers and directors | C10: Corporate Managers & Directors | D10: 3 | E10: 5 | F10: 5 | G10: 8 | H10: 5 | I10: 5 | J10: 8 | K10: 8 | L10: 0 | M10: 2 | N10: 0 | O10: 12 | P10: 10 | Q10: 8 | R10: 15 | S10: 0 | T10: 3 | U10: 3 | V10: =SUM(D10:U10) -> 100
A11: 1135 | B11: Charitable organisation managers and directors | C11: Corporate Managers & Directors | D11: 3 | E11: 5 | F11: 8 | G11: 5 | H11: 5 | I11: 2 | J11: 12 | K11: 8 | L11: 0 | M11: 2 | N11: 1 | O11: 15 | P11: 10 | Q11: 3 | R11: 12 | S11: 0 | T11: 5 | U11: 4 | V11: =SUM(D11:U11) -> 100
A12: 1136 | B12: Research and development managers | C12: Corporate Managers & Directors | D12: 2 | E12: 3 | F12: 15 | G12: 5 | H12: 5 | I12: 3 | J12: 12 | K12: 3 | L12: 0 | M12: 15 | N12: 2 | O12: 15 | P12: 3 | Q12: 5 | R12: 10 | S12: 0 | T12: 2 | U12: 0 | V12: =SUM(D12:U12) -> 100
A13: 1137 | B13: Information technology directors | C13: Corporate Managers & Directors | D13: 2 | E13: 3 | F13: 8 | G13: 5 | H13: 5 | I13: 2 | J13: 10 | K13: 5 | L13: 0 | M13: 15 | N13: 1 | O13: 18 | P13: 8 | Q13: 3 | R13: 12 | S13: 0 | T13: 3 | U13: 0 | V13: =SUM(D13:U13) -> 100
... A413: 9279 | B413: Elementary cleaning occupations n.e.c. | C413: Elementary Administration & Service Occupations | D413: 2 | E413: 1 | F413: 1 | G413: 2 | H413: 1 | I413: 2 | J413: 1 | K413: 3 | L413: 0 | M413: 2 | N413: 0 | O413: 2 | P413: 1 | Q413: 2 | R413: 2 | S413: 0 | T413: 15 | U413: 63 | V413: =SUM(D413:U413) -> 100

Sheet Calculation
A1: SOC Code | B1: Occupation Title | C1: Sub-Major Group | D1: Est. Employment | E1: Raw AI Exposure (May 2026) | F1: Practical Impact (May 2026) | G1: Hrs Freed / Worker / Week | H1: Annual Hrs Freed / Worker | I1: Total Weekly Hrs Freed (000s) | J1: FTE Equivalent Capacity
A2: 1111 | B2: Chief executives and senior officials | C2: Corporate Managers & Directors | D2: 167737 | E2: 0.6486 | F2: 0.3243 | G2: 12 | H2: 564 | I2: 2012.7 | J2: 54397
A3: 1112 | B3: Elected officers and representatives | C3: Corporate Managers & Directors | D3: 167737 | E3: 0.6534 | F3: 0.3267 | G3: 12.1 | H3: 568 | I3: 2027.6 | J3: 54800
A4: 1113 | B4: Senior police officers | C4: Corporate Managers & Directors | D4: 167737 | E4: 0.5895 | F4: 0.2948 | G4: 10.9 | H4: 513 | I4: 1829.3 | J4: 49440
A5: 1114 | B5: Officers in armed forces | C5: Corporate Managers & Directors | D5: 167737 | E5: 0.5992 | F5: 0.2996 | G5: 11.1 | H5: 521 | I5: 1859.4 | J5: 50254
A6: 1115 | B6: Senior officers in fire, ambulance, prison and related services | C6: Corporate Managers & Directors | D6: 167737 | E6: 0.5781 | F6: 0.2891 | G6: 10.7 | H6: 503 | I6: 1793.9 | J6: 48484
A7: 1131 | B7: Financial managers and directors | C7: Corporate Managers & Directors | D7: 167737 | E7: 0.6723 | F7: 0.3362 | G7: 12.4 | H7: 585 | I7: 2086.2 | J7: 56385
A8: 1132 | B8: Marketing, sales and advertising directors | C8: Corporate Managers & Directors | D8: 167737 | E8: 0.6887 | F8: 0.3444 | G8: 12.7 | H8: 599 | I8: 2137.1 | J8: 57760
A9: 1133 | B9: Purchasing managers and directors | C9: Corporate Managers & Directors | D9: 167737 | E9: 0.644 | F9: 0.322 | G9: 11.9 | H9: 560 | I9: 1998.4 | J9: 54011
A10: 1134 | B10: Human resource managers and directors | C10: Corporate Managers & Directors | D10: 167737 | E10: 0.6526 | F10: 0.3263 | G10: 12.1 | H10: 567 | I10: 2025.1 | J10: 54733
A11: 1135 | B11: Charitable organisation managers and directors | C11: Corporate Managers & Directors | D11: 167737 | E11: 0.6493 | F11: 0.3246 | G11: 12 | H11: 565 | I11: 2014.9 | J11: 54456
A12: 1136 | B12: Research and development managers | C12: Corporate Managers & Directors | D12: 167737 | E12: 0.73 | F12: 0.365 | G12: 13.5 | H12: 635 | I12: 2265.3 | J12: 61224
A13: 1137 | B13: Information technology directors | C13: Corporate Managers & Directors | D13: 167737 | E13: 0.6837 | F13: 0.3419 | G13: 12.6 | H13: 594 | I13: 2121.6 | J13: 57341
... A413: 9279 | B413: Elementary cleaning occupations n.e.c. | C413: Elementary Administration & Service Occupations | D413: 94680 | E413: 0.2297 | F413: 0.1263 | G413: 4.7 | H413: 220 | I413: 442.6 | J413: 11961
A414: TOTALS | D414: =SUM(D2:D413) -> 34250030 | E414: =SUMPRODUCT(D2:D413,E2:E413)/SUM(D2:D413) -> 0.55930494 | F414: =SUMPRODUCT(D2:D413,F2:F413)/SUM(D2:D413) -> 0.29502847 | G414: =SUMPRODUCT(D2:D413,G2:G413)/SUM(D2:D413) -> 10.917283 | H414: =G414*47 -> 513.1123 | I414: =SUM(I2:I413) -> 373870.4 | J414: =SUM(J2:J413) -> 10104614

Sheet Summary Dashboard
A1: AWA AI IMPACT ASSESSMENT: ALL 412 UK OCCUPATIONS (SOC 2020)
A2: Task Decomposition Model — May 2026 Frontier Calibration
A4: KEY METRICS
A5: Total Occupations Assessed | C5: =412 -> 412
A6: Total UK Employment (estimated) | C6: =Calculation!D414 -> 34250030
A7: Adoption Discount Factor | B7: 0.48–0.60 (sector-specific) | C7: ='Task Categories'!C21 -> 0.6
A8: Standard Working Week (hrs) | C8: ='Task Categories'!C22 -> 37
A10: AGGREGATE RESULTS
A11: Employment-Weighted Mean AI Exposure | B11: 0.5593 | C11: =Calculation!E414 -> 0.55930494
A12: Employment-Weighted Mean Practical Impact | B12: 0.295 | C12: =Calculation!F414 -> 0.29502847
A13: Mean Hours Freed per Worker per Week | B13: 10.9 | C13: =Calculation!G414 -> 10.917283
A14: Mean Hours Freed per Worker per Year (47 wks) | B14: 513 | C14: =Calculation!H414 -> 513.1123
A15: Total Weekly Hours Freed (000s) | C15: =Calculation!I414 -> 373870.4
A16: Total FTE Equivalent Capacity Created | C16: =Calculation!J414 -> 10104614
A19: Rank | B19: SOC Code | C19: Occupation Title | D19: Sub-Major Group | E19: Est. Employment | F19: Raw AI Exposure | G19: Practical Impact % | H19: Hrs Freed/Worker/Week | I19: FTE Capacity Created | J19: Impact Band
A20: 1 | B20: 1111 | C20: Chief executives and senior officials | D20: Corporate Managers & Directors | E20: =Calculation!D2 -> 167737 | F20: =Calculation!E2 -> 0.6486 | G20: =Calculation!F2 -> 0.3243 | H20: =Calculation!G2 -> 12 | I20: =Calculation!J2 -> 54397 | J20: =IF(G20>=35%,"Transformative",IF(G20>=25%,"High",IF(G20>=15%,"Moderate","Low"))) -> High
A21: 2 | B21: 1112 | C21: Elected officers and representatives | D21: Corporate Managers & Directors | E21: =Calculation!D3 -> 167737 | F21: =Calculation!E3 -> 0.6534 | G21: =Calculation!F3 -> 0.3267 | H21: =Calculation!G3 -> 12.1 | I21: =Calculation!J3 -> 54800 | J21: =IF(G21>=35%,"Transformative",IF(G21>=25%,"High",IF(G21>=15%,"Moderate","Low"))) -> High
A22: 3 | B22: 1113 | C22: Senior police officers | D22: Corporate Managers & Directors | E22: =Calculation!D4 -> 167737 | F22: =Calculation!E4 -> 0.5895 | G22: =Calculation!F4 -> 0.2948 | H22: =Calculation!G4 -> 10.9 | I22: =Calculation!J4 -> 49440 | J22: =IF(G22>=35%,"Transformative",IF(G22>=25%,"High",IF(G22>=15%,"Moderate","Low"))) -> High
A23: 4 | B23: 1114 | C23: Officers in armed forces | D23: Corporate Managers & Directors | E23: =Calculation!D5 -> 167737 | F23: =Calculation!E5 -> 0.5992 | G23: =Calculation!F5 -> 0.2996 | H23: =Calculation!G5 -> 11.1 | I23: =Calculation!J5 -> 50254 | J23: =IF(G23>=35%,"Transformative",IF(G23>=25%,"High",IF(G23>=15%,"Moderate","Low"))) -> High
A24: 5 | B24: 1115 | C24: Senior officers in fire, ambulance, prison and related services | D24: Corporate Managers & Directors | E24: =Calculation!D6 -> 167737 | F24: =Calculation!E6 -> 0.5781 | G24: =Calculation!F6 -> 0.2891 | H24: =Calculation!G6 -> 10.7 | I24: =Calculation!J6 -> 48484 | J24: =IF(G24>=35%,"Transformative",IF(G24>=25%,"High",IF(G24>=15%,"Moderate","Low"))) -> High
A25: 6 | B25: 1131 | C25: Financial managers and directors | D25: Corporate Managers & Directors | E25: =Calculation!D7 -> 167737 | F25: =Calculation!E7 -> 0.6723 | G25: =Calculation!F7 -> 0.3362 | H25: =Calculation!G7 -> 12.4 | I25: =Calculation!J7 -> 56385 | J25: =IF(G25>=35%,"Transformative",IF(G25>=25%,"High",IF(G25>=15%,"Moderate","Low"))) -> High
A26: 7 | B26: 1132 | C26: Marketing, sales and advertising directors | D26: Corporate Managers & Directors | E26: =Calculation!D8 -> 167737 | F26: =Calculation!E8 -> 0.6887 | G26: =Calculation!F8 -> 0.3444 | H26: =Calculation!G8 -> 12.7 | I26: =Calculation!J8 -> 57760 | J26: =IF(G26>=35%,"Transformative",IF(G26>=25%,"High",IF(G26>=15%,"Moderate","Low"))) -> High
A27: 8 | B27: 1133 | C27: Purchasing managers and directors | D27: Corporate Managers & Directors | E27: =Calculation!D9 -> 167737 | F27: =Calculation!E9 -> 0.644 | G27: =Calculation!F9 -> 0.322 | H27: =Calculation!G9 -> 11.9 | I27: =Calculation!J9 -> 54011 | J27: =IF(G27>=35%,"Transformative",IF(G27>=25%,"High",IF(G27>=15%,"Moderate","Low"))) -> High
A28: 9 | B28: 1134 | C28: Human resource managers and directors | D28: Corporate Managers & Directors | E28: =Calculation!D10 -> 167737 | F28: =Calculation!E10 -> 0.6526 | G28: =Calculation!F10 -> 0.3263 | H28: =Calculation!G10 -> 12.1 | I28: =Calculation!J10 -> 54733 | J28: =IF(G28>=35%,"Transformative",IF(G28>=25%,"High",IF(G28>=15%,"Moderate","Low"))) -> High
A29: 10 | B29: 1135 | C29: Charitable organisation managers and directors | D29: Corporate Managers & Directors | E29: =Calculation!D11 -> 167737 | F29: =Calculation!E11 -> 0.6493 | G29: =Calculation!F11 -> 0.3246 | H29: =Calculation!G11 -> 12 | I29: =Calculation!J11 -> 54456 | J29: =IF(G29>=35%,"Transformative",IF(G29>=25%,"High",IF(G29>=15%,"Moderate","Low"))) -> High
A30: 11 | B30: 1136 | C30: Research and development managers | D30: Corporate Managers & Directors | E30: =Calculation!D12 -> 167737 | F30: =Calculation!E12 -> 0.73 | G30: =Calculation!F12 -> 0.365 | H30: =Calculation!G12 -> 13.5 | I30: =Calculation!J12 -> 61224 | J30: =IF(G30>=35%,"Transformative",IF(G30>=25%,"High",IF(G30>=15%,"Moderate","Low"))) -> Transformative
A31: 12 | B31: 1137 | C31: Information technology directors | D31: Corporate Managers & Directors | E31: =Calculation!D13 -> 167737 | F31: =Calculation!E13 -> 0.6837 | G31: =Calculation!F13 -> 0.3419 | H31: =Calculation!G13 -> 12.6 | I31: =Calculation!J13 -> 57341 | J31: =IF(G31>=35%,"Transformative",IF(G31>=25%,"High",IF(G31>=15%,"Moderate","Low"))) -> High
... A431: 412 | B431: 9279 | C431: Elementary cleaning occupations n.e.c. | D431: Elementary Administration & Service Occupations | E431: =Calculation!D413 -> 94680 | F431: =Calculation!E413 -> 0.2297 | G431: =Calculation!F413 -> 0.1263 | H431: =Calculation!G413 -> 4.7 | I431: =Calculation!J413 -> 11961 | J431: =IF(G431>=35%,"Transformative",IF(G431>=25%,"High",IF(G431>=15%,"Moderate","Low"))) -> Low

Sheet Sub-Major Group Summary
A1: Sub-Major Group | B1: Group Name | C1: Occupations Count | D1: Est. Employment (000s) | E1: Mean Raw Exposure | F1: Mean Practical Impact | G1: Mean Hrs Freed/Worker/Week | H1: Total FTE Capacity Created | I1: Highest Impact Occupation | J1: Lowest Impact Occupation
A2: 11 | B2: Corporate Managers & Directors | C2: 19 | D2: 3187 | E2: 0.6309 | F2: 0.3154 | G2: 11.7 | H2: 1005290 | I2: Research and development managers | J2: Production managers and directors in construction
A3: 12 | B3: Other Managers & Proprietors | C3: 22 | D3: 2041 | E3: 0.6053 | F3: 0.3329 | G3: 12.3 | H3: 679456 | I3: Managers and directors in the creative industries | J3: Managers and proprietors in agriculture and hortic
A4: 21 | B4: Science, Research, Engineering & Technology Professionals | C4: 28 | D4: 2106 | E4: 0.7609 | F4: 0.3805 | G4: 14.1 | H4: 801266 | I4: Actuaries, economists and statisticians | J4: IT managers
A5: 22 | B5: Health Professionals | C5: 26 | D5: 1847 | E5: 0.6055 | F5: 0.333 | G5: 12.3 | H5: 615066 | I5: Health promotion officers | J5: Dental practitioners
A6: 23 | B6: Teaching & Educational Professionals | C6: 11 | D6: 1712 | E6: 0.6726 | F6: 0.3901 | G6: 14.4 | H6: 667836 | I6: Higher education teaching professionals | J6: Nursery education teaching professionals
A7: 24 | B7: Business, Media & Public Service Professionals | C7: 31 | D7: 2389 | E7: 0.7067 | F7: 0.3534 | G7: 13.1 | H7: 844166 | I7: Business and related research professionals | J7: Youth work professionals
A8: 31 | B8: Science, Engineering & Technology Associate Professionals | C8: 12 | D8: 684 | E8: 0.6387 | F8: 0.3194 | G8: 11.8 | H8: 218447 | I8: Database administrators and web content technician | J8: Building and civil engineering technicians
A9: 32 | B9: Health & Social Care Associate Professionals | C9: 13 | D9: 931 | E9: 0.5539 | F9: 0.3046 | G9: 11.3 | H9: 283623 | I9: Higher level teaching assistants | J9: Veterinary nurses
A10: 33 | B10: Protective Service Occupations | C10: 5 | D10: 438 | E10: 0.5233 | F10: 0.2878 | G10: 10.6 | H10: 126058 | I10: Police officers (sergeant and below) | J10: NCOs and other ranks
A11: 34 | B11: Culture, Media & Sports Occupations | C11: 14 | D11: 571 | E11: 0.5527 | F11: 0.2763 | G11: 10.2 | H11: 157785 | I11: Authors, writers and translators | J11: Sports players
A12: 35 | B12: Business & Public Service Associate Professionals | C12: 34 | D12: 2197 | E12: 0.6504 | F12: 0.3252 | G12: 12 | H12: 714442 | I12: Data analysts | J12: Train and tram drivers
A13: 41 | B13: Administrative Occupations | C13: 20 | D13: 2355 | E13: 0.6947 | F13: 0.3335 | G13: 12.3 | H13: 785278 | I13: Credit controllers | J13: Office supervisors
... A27: 92 | B27: Elementary Administration & Service Occupations | C27: 25 | D27: 2367 | E27: 0.3049 | F27: 0.1677 | G27: 6.2 | H27: 396997 | I27: Bar and catering supervisors | J27: Road sweepers
A29: TOTALS | C29: =SUM(C2:C27) -> 412 | D29: =SUM(D2:D27) -> 34250 | H29: =SUM(H2:H27) -> 10104618

Sheet Four-Scenario Summary
A1: Four Capability Scenarios: GPT-4 Era → Claude 4.6 → May 2026 Frontier → 5yr Projected
A2: Task scores recalibrated at each point. May 2026 uses sector-specific adoption discounts. All scenarios include capability amplification.
A4: Task Score Comparison
A5: Task | B5: GPT-4 Era (2023) | C5: Claude 4.6 (Feb 2026) | D5: May 2026 Frontier | E5: 5yr Proj (2031) | F5: Change GPT4→May26 | G5: Evidence for May 2026 revision
A6: Structured Data Entry & Processing | B6: 0.92 | C6: 0.95 | D6: 0.96 | E6: 0.98 | F6: 0.04 | G6: Near ceiling. Marginal improvement.
A7: Routine Text Generation | B7: 0.88 | C7: 0.93 | D7: 0.94 | E7: 0.98 | F7: 0.06 | G7: Marginal. Already very high.
A8: Information Retrieval & Synthesis | B8: 0.85 | C8: 0.91 | D8: 0.93 | E8: 0.979 | F8: 0.08 | G8: Code execution + agentic search now standard.
A9: Scheduling & Coordination | B9: 0.82 | C9: 0.88 | D9: 0.9 | E9: 0.97 | F9: 0.08 | G9: Enterprise agents (OpenAI Frontier, Copilot) handling complex customer workflows.
A10: Routine Numerical Analysis | B10: 0.8 | C10: 0.87 | D10: 0.88 | E10: 0.964 | F10: 0.08 | G10: Agentic workflows now production-grade.
A11: Classification & Sorting | B11: 0.78 | C11: 0.86 | D11: 0.88 | E11: 0.964 | F11: 0.1 | G11: Deep research + agentic search tools standard.
A12: Complex Document Drafting | B12: 0.7 | C12: 0.82 | D12: 0.85 | E12: 0.955 | F12: 0.15 | G12: Agent workflows for invoicing, payroll now deployed.
A13: Customer/Client Communication | B13: 0.65 | C13: 0.8 | D13: 0.82 | E13: 0.946 | F13: 0.17 | G13: Long-context + agent review of full regulatory documents; AWS Security Agent.
A14: Translation & Language Services | B14: 0.75 | C14: 0.79 | D14: 0.82 | E14: 0.946 | F14: 0.07 | G14: Near-human quality email/Slack. Marginal.
A15: Technical Analysis & Problem-Solving | B15: 0.55 | C15: 0.74 | D15: 0.78 | E15: 0.934 | F15: 0.23 | G15: AWS Security Agent -90% testing time. Code review agents widespread.
A16: Creative Design & Content | B16: 0.5 | C16: 0.75 | D16: 0.8 | E16: 0.94 | F16: 0.3 | G16: Kiro: 1M lines/month, 80% daily dev adoption at Motorway.
A17: Strategic Judgement & Decision-Making | B17: 0.35 | C17: 0.55 | D17: 0.58 | E17: 0.811 | F17: 0.23 | G17: Better reasoning but still lacks lived experience/accountability.
... A23: Outdoor/Physical Labour | B23: 0.05 | C23: 0.06 | D23: 0.07 | E23: 0.256 | F23: 0.02 | G23: Essentially no change.
A26: Headline Metrics
A27: Metric | B27: GPT-4 Era | C27: Claude 4.6 | D27: May 2026 | E27: 5yr Projected
A28: Mean raw exposure | B28: 0.44215551 | C28: 0.53615503 | D28: 0.55930494 | E28: 0.7160534
A29: Mean practical impact (substitution) | B29: 0.26529331 | C29: 0.29488527 | D29: 0.29502506 | E29: 0.32222403
A30: Substitution hrs/worker/week | B30: 9.8158524 | C30: 10.910755 | D30: 10.915927 | E30: 11.922289
A31: Substitution FTE capacity (M) | B31: 9.0863037 | C31: 10.099829 | D31: 10.104617 | E31: 11.036183
A32: Combined hrs/worker/week (with amplification) | B32: 15.506458 | C32: 17.267245 | D32: 17.103645 | E32: 18.607041
A33: Combined FTE capacity (M) | B33: 14.353963 | C33: 15.983883 | D33: 15.832442 | E33: 17.2241
A36: Adoption Discounts
A37: GPT-4 era: 0.60 (flat) | Claude 4.6: 0.55 (flat) | 5yr: 0.45 (flat)
A38: May 2026: Sector-specific discounts (see below)
A40: Occupational Family | B40: Discount | C40: Rationale
A41: Administrative Occupations | B41: 0.48 | C41: Fast adopters — enterprise agents deployed, high digital maturity
A42: Business & Public Service Associate Professionals | B42: 0.5 | C42: Professional/knowledge work — strong tooling ecosystem, proven ROI
A43: Business, Media & Public Service Professionals | B43: 0.5 | C43: Professional/knowledge work — strong tooling ecosystem, proven ROI
A44: Caring Personal Service Occupations | B44: 0.6 | C44: Minimal adoption — physical work, little AI interface
A45: Community & Civil Enforcement Occupations | B45: 0.58 | C45: Slower adoption — manual work context, limited AI tooling
A46: Corporate Managers & Directors | B46: 0.5 | C46: Professional/knowledge work — strong tooling ecosystem, proven ROI
A47: Culture, Media & Sports Occupations | B47: 0.5 | C47: Professional/knowledge work — strong tooling ecosystem, proven ROI
A48: Customer Service Occupations | B48: 0.48 | C48: Fast adopters — enterprise agents deployed, high digital maturity
A49: Elementary Administration & Service Occupations | B49: 0.55 | C49: Mixed adoption — partial deployment, regulatory caution
A50: Elementary Trades & Related Occupations | B50: 0.6 | C50: Minimal adoption — physical work, little AI interface
A51: Health & Social Care Associate Professionals | B51: 0.55 | C51: Mixed adoption — partial deployment, regulatory caution
...

Sheet May 2026 Frontier
A1: May 2026 Frontier: Per-Occupation Analysis with Sector-Specific Discounts
A3: SOC | B3: Occupation | C3: SMG | D3: Emp | E3: Discount | F3: Raw | G3: PI | H3: Sub hrs | I3: Mult | J3: Amp hrs | K3: Combined hrs
A4: 2161 | B4: Actuaries, economists and statisticians | C4: Science, Research, Engineering & Technology Professionals | D4: 75214 | E4: 0.5 | F4: 0.825 | G4: 0.4125 | H4: 15.2625 | I4: 2.5 | J4: 22.89375 | K4: 38.15625
A5: 2162 | B5: Other researchers, unspecified discipline | C5: Science, Research, Engineering & Technology Professionals | D5: 75214 | E5: 0.5 | F5: 0.8153 | G5: 0.40765 | H5: 15.08305 | I5: 2.5 | J5: 22.624575 | K5: 37.707625
A6: 2111 | B6: Chemical scientists | C6: Science, Research, Engineering & Technology Professionals | D6: 75214 | E6: 0.5 | F6: 0.7916 | G6: 0.3958 | H6: 14.6446 | I6: 2.5 | J6: 21.9669 | K6: 36.6115
A7: 2112 | B7: Biological scientists | C7: Science, Research, Engineering & Technology Professionals | D7: 75214 | E7: 0.5 | F7: 0.7916 | G7: 0.3958 | H7: 14.6446 | I7: 2.5 | J7: 21.9669 | K7: 36.6115
A8: 2114 | B8: Physical scientists | C8: Science, Research, Engineering & Technology Professionals | D8: 75214 | E8: 0.5 | F8: 0.7916 | G8: 0.3958 | H8: 14.6446 | I8: 2.5 | J8: 21.9669 | K8: 36.6115
A9: 2113 | B9: Biochemists and biomedical scientists | C9: Science, Research, Engineering & Technology Professionals | D9: 75214 | E9: 0.5 | F9: 0.7871 | G9: 0.39355 | H9: 14.56135 | I9: 2.5 | J9: 21.842025 | K9: 36.403375
A10: 2119 | B10: Natural and social science professionals n.e.c. | C10: Science, Research, Engineering & Technology Professionals | D10: 75214 | E10: 0.5 | F10: 0.7844 | G10: 0.3922 | H10: 14.5114 | I10: 2.5 | J10: 21.7671 | K10: 36.2785
A11: 2135 | B11: Cyber security professionals | C11: Science, Research, Engineering & Technology Professionals | D11: 75214 | E11: 0.5 | F11: 0.7775 | G11: 0.38875 | H11: 14.38375 | I11: 2.5 | J11: 21.575625 | K11: 35.959375
A12: 2141 | B12: Web design and development professionals | C12: Science, Research, Engineering & Technology Professionals | D12: 75214 | E12: 0.5 | F12: 0.769 | G12: 0.3845 | H12: 14.2265 | I12: 2.5 | J12: 21.33975 | K12: 35.56625
A13: 2121 | B13: Civil engineers | C13: Science, Research, Engineering & Technology Professionals | D13: 75214 | E13: 0.5 | F13: 0.7689 | G13: 0.38445 | H13: 14.22465 | I13: 2.5 | J13: 21.336975 | K13: 35.561625
A14: 2133 | B14: IT business analysts, architects and systems designers | C14: Science, Research, Engineering & Technology Professionals | D14: 75214 | E14: 0.5 | F14: 0.7688 | G14: 0.3844 | H14: 14.2228 | I14: 2.5 | J14: 21.3342 | K14: 35.557
A15: 2136 | B15: IT quality and testing professionals | C15: Science, Research, Engineering & Technology Professionals | D15: 75214 | E15: 0.5 | F15: 0.7683 | G15: 0.38415 | H15: 14.21355 | I15: 2.5 | J15: 21.320325 | K15: 35.533875
... A415: 9271 | B415: Road sweepers | C415: Elementary Administration & Service Occupations | D415: 94680 | E415: 0.55 | F415: 0.1961 | G415: 0.107855 | H415: 3.990635 | I415: 1 | J415: 0 | K415: 3.990635

Sheet Capability Multipliers
A1: Capability Amplification Framework
A2: Beyond task substitution: AI enables work that was previously economically unfeasible
A4: Capability Multiplier Definitions
A5: Multiplier | B5: Description | C5: Example | D5: Employment | E5: % Workforce | F5: Mean Sub PI | G5: Mean Combined PI
A6: 2.5x | C6: Scientists, researchers, actuaries — AI enables experimentation at previously impossible scales | D6: 2105992 | E6: 0.061488764 | F6: 0.36150214 | G6: 0.90375536
A7: 2.0x | C7: Engineers, IT professionals, designers — AI enables broader prototyping, testing and analysis | D7: 3644019 | E7: 0.10639462 | F7: 0.31929985 | G7: 0.6385997
A8: 1.8x | C8: Directors, business professionals, HR — AI enables richer intelligence and deeper due diligence | D8: 7231003 | E8: 0.21112399 | F8: 0.29416605 | G8: 0.52949888
A9: 1.5x | C9: Teachers, health associates, other managers — AI enables expanded educational and clinical capabilities | D9: 4683997 | E9: 0.13675892 | F9: 0.28690216 | G9: 0.43035325
A10: 1.3x | C10: Sales, customer service, protective — AI enables better personalisation and faster resolution | D10: 2641002 | E10: 0.07710948 | F10: 0.29475372 | G10: 0.38317983
A11: 1.2x | C11: Admin, secretarial, leisure — AI enables marginally faster processing | D11: 3982004 | E11: 0.11626279 | F11: 0.33367199 | G11: 0.40040639
A12: 1.1x | C12: Skilled trades, caring roles — AI provides limited new capability | D12: 4920005 | E12: 0.14364966 | F12: 0.18141621 | G12: 0.19955783
A13: 1.0x | C13: Operatives, drivers, elementary — no material amplification from AI | D13: 5042008 | E13: 0.14721178 | F13: 0.13700632 | G13: 0.13700632
A16: Key Assumptions
A17: Multipliers are applied to substitution hours (not total working hours)
A18: Combined value = Substitution hours × Multiplier
A19: Amplification represents NEW productive output AI enables, not just time saved
A20: Examples: research at scale, scenario testing, broader analysis, faster prototyping
A21: Multipliers assigned by Sub-Major Group (occupational family), adjustable per client
A22: Multiplier of 1.0 = pure substitution; 2.5 = each hour saved generates 2.5 hours of new capability

Sheet Combined Impact
A1: Combined Impact: Task Substitution + Capability Amplification
A3: Headline Comparison
A4: Metric | B4: Substitution Only | C4: Amplification Only | D4: Combined | E4: Amplification Uplift
A5: Mean practical impact | B5: 0.26529331 | C5: 0.15380015 | D5: 0.41909345 | E5: 0.57973624
A6: Hours per worker/week | B6: 9.8158524 | C6: 5.6906054 | D6: 15.506458 | E6: 0.57973624
A7: FTE capacity (millions) | B7: 9.0863037 | C7: 5.2676596 | D7: 14.353963 | E7: 0.57973624
A10: Impact by Occupational Family
A11: Sub-Major Group | B11: Mult | C11: Employment | D11: Sub hrs/wk | E11: Amp hrs/wk | F11: Combined hrs/wk
A12: Science, Research, Engineering & Technology Professionals | B12: 2.5 | C12: 2105992 | D12: 13.375579 | E12: 20.063369 | F12: 33.438948
A13: Business, Media & Public Service Professionals | B13: 2 | C13: 2389015 | D13: 12.589477 | E13: 12.589477 | F13: 25.178954
A14: Science, Engineering & Technology Associate Professionals | B14: 2 | C14: 684000 | D14: 11.22025 | E14: 11.22025 | F14: 22.4405
A15: Business & Public Service Associate Professionals | B15: 1.8 | C15: 2197012 | D15: 11.549681 | E15: 9.2397445 | F15: 20.789425
A16: Corporate Managers & Directors | B16: 1.8 | C16: 3187003 | D16: 10.731597 | E16: 8.5852775 | F16: 19.316874
A17: Health Professionals | B17: 1.8 | C17: 1846988 | D17: 10.355702 | E17: 8.2845618 | F17: 18.640264
A18: Culture, Media & Sports Occupations | B18: 2 | C18: 571004 | D18: 9.2813443 | E18: 9.2813443 | F18: 18.562689
A19: Secretarial & Related Occupations | B19: 1.2 | C19: 754999 | D19: 14.606966 | E19: 2.9213931 | F19: 17.528359
A20: Customer Service Occupations | B20: 1.3 | C20: 556002 | D20: 13.26968 | E20: 3.980904 | F20: 17.250584
A21: Teaching & Educational Professionals | B21: 1.5 | C21: 1711996 | D21: 11.360144 | E21: 5.6800718 | F21: 17.040215
A22: Administrative Occupations | B22: 1.2 | C22: 2355000 | D22: 13.189242 | E22: 2.6378484 | F22: 15.82709
A23: Other Managers & Proprietors | B23: 1.5 | C23: 2041006 | D23: 10.537432 | E23: 5.2687159 | F23: 15.806148
... A37: Elementary Trades & Related Occupations | B37: 1 | C37: 478000 | D37: 3.99933 | E37: 0 | F37: 3.99933
